<?xml version="1.0" ?>
<!-- =================================================================================== -->
<!-- |    This document was autogenerated by xacro from /home/akiyoshi/work/fp_ws/install/pingu_description/share/pingu_description/urdf/pingu.urdf.xacro | -->
<!-- |    EDITING THIS FILE BY HAND IS NOT RECOMMENDED                                 | -->
<!-- =================================================================================== -->
<robot name="pingu">
 <!-- Enable right arm -->
 <link name="world"/>
 <joint name="base_joint" type="floating">
  <origin rpy="0 0 0" xyz="0 0 .2875"/>
  <parent link="world"/>
  <child link="base_link"/>
 </joint>
 <!-- Base description -->
 <link name="base_link">
  <visual>
   <geometry>
    <mesh filename="package://pingu_description/mesh/base_link.stl" scale="1 1 1"/>
   </geometry>
   <material name="black_transparent">
    <color rgba="0 0 0 0.5"/>
   </material>
   <origin rpy="0 0 0.785398163375" xyz="0 0 0"/>
  </visual>
  <collision>
   <geometry>
    <mesh filename="package://pingu_description/mesh/base_link.stl" scale="1 1 1"/>
   </geometry>
   <origin rpy="0 0 0.785398163375" xyz="0 0 0"/>
   <!-- 0 0 0.3276 for box -->
  </collision>
  <inertial>
   <mass value="23.0"/>
   <origin rpy="0 0 0.785398163375" xyz="0 0 0"/>
   <inertia ixx="0.5" ixy="0" ixz="0" iyy="0.5" iyz="0" izz="0.5"/>
  </inertial>
 </link>
 <joint name="base_joint" type="fixed">
  <origin rpy="0 0 0" xyz="0 0 .2875"/>
  <parent link="base_link"/>
  <child link="rw_base"/>
 </joint>
 <!-- Base Link -->
 <link name="rw_base">
  <collision>
   <origin rpy="0 0 0" xyz="0 0 0"/>
   <geometry>
    <mesh filename="package://rw_ros2_control/mesh/rw_base.stl" scale="1 1 1"/>
   </geometry>
  </collision>
  <visual>
   <origin rpy="0 0 0.785" xyz="0 0 0"/>
   <geometry>
    <mesh filename="package://rw_ros2_control/mesh/rw_base.stl" scale="1 1 1"/>
   </geometry>
   <material name="orange"/>
  </visual>
  <inertial>
   <origin rpy="0 0 0.785" xyz="0 0 0"/>
   <mass value="1.0"/>
   <inertia ixx="0.0001" ixy="0.0" ixz="0.0" iyy="0.0001" iyz="0.0" izz="0.0001"/>
  </inertial>
 </link>
 <!-- Middle Link -->
 <link name="rw_rotor">
  <collision>
   <origin rpy="0 0 0" xyz="0 0 0"/>
   <geometry>
    <cylinder length="0.05" radius="0.1"/>
   </geometry>
  </collision>
  <visual>
   <origin rpy="0 0 0" xyz="0 0 0"/>
   <geometry>
    <cylinder length="0.05" radius="0.1"/>
   </geometry>
   <material name="orange"/>
  </visual>
  <inertial>
   <origin rpy="0 0 0" xyz="0 0 0"/>
   <mass value="1.0"/>
   <inertia ixx="0.0001" ixy="0.0" ixz="0.0" iyy="0.0001" iyz="0.0" izz="0.0001"/>
  </inertial>
 </link>
 <joint name="rw_joint" type="revolute">
  <parent link="rw_base"/>
  <child link="rw_rotor"/>
  <origin rpy="0 0 0" xyz="0 0 0.05"/>
  <axis xyz="0 0 1"/>
  <limit effort="10.0" lower="-3.14" upper="3.14" velocity="1.0"/>
  <dynamics damping="0.5" friction="0.5"/>
 </joint>
 <joint name="left_base_joint" type="fixed">
  <origin rpy="0 0 0.785398163375" xyz="0.18384776309900003 0.18384776309900003 .3475"/>
  <parent link="base_link"/>
  <child link="left_link0"/>
 </joint>
 <link name="left_link0">
  <visual>
   <origin rpy="0 0 0" xyz="0 0 0"/>
   <geometry>
    <mesh filename="package://levion_arm_ros2_control/mesh/Link0.STL" scale="1 1 1"/>
   </geometry>
   <material name="levion_black">
    <color rgba="0.3 0.3 0.3 1.0"/>
   </material>
  </visual>
  <collision>
   <origin rpy="0 0 0" xyz="0 0 0"/>
   <geometry>
    <mesh filename="package://levion_arm_ros2_control/mesh/Link0.STL" scale="1 1 1"/>
   </geometry>
  </collision>
  <inertial>
   <origin rpy="0 0 0" xyz="0 0 0"/>
   <mass value="0.5"/>
   <inertia ixx="0.0005" ixy="0.0" ixz="0.0" iyy="0.0005" iyz="0.0" izz="0.0005"/>
  </inertial>
 </link>
 <link name="left_link1">
  <visual>
   <origin rpy="0 0 0" xyz="0 0 0"/>
   <geometry>
    <mesh filename="package://levion_arm_ros2_control/mesh/Link1.STL" scale="1 1 1"/>
   </geometry>
   <material name="levion_black">
    <color rgba="0.3 0.3 0.3 1.0"/>
   </material>
  </visual>
  <collision>
   <origin rpy="0 0 0" xyz="0 0 0"/>
   <geometry>
    <mesh filename="package://levion_arm_ros2_control/mesh/Link1.STL" scale="1 1 1"/>
   </geometry>
  </collision>
  <inertial>
   <origin rpy="0 0 0" xyz="0.05 0 0"/>
   <mass value="0.6"/>
   <inertia ixx="0.0006" ixy="0.0" ixz="0.0" iyy="0.0006" iyz="0.0" izz="0.0006"/>
  </inertial>
 </link>
 <link name="left_link2">
  <visual>
   <origin rpy="0 0 0" xyz="0 0 0"/>
   <geometry>
    <mesh filename="package://levion_arm_ros2_control/mesh/Link2.STL" scale="1 1 1"/>
   </geometry>
   <material name="levion_black">
    <color rgba="0.3 0.3 0.3 1.0"/>
   </material>
  </visual>
  <collision>
   <origin rpy="0 0 0" xyz="0 0 0"/>
   <geometry>
    <mesh filename="package://levion_arm_ros2_control/mesh/Link2.STL" scale="1 1 1"/>
   </geometry>
  </collision>
  <inertial>
   <origin rpy="0 0 0" xyz="0 0 0"/>
   <mass value="0.1"/>
   <inertia ixx="0.0001" ixy="0.0" ixz="0.0" iyy="0.0001" iyz="0.0" izz="0.0001"/>
  </inertial>
 </link>
 <link name="left_tool_link">
  </link>
 <joint name="left_shoulder_joint" type="revolute">
  <origin rpy="0 0 0" xyz="0 0 0.0439"/>
  <parent link="left_link0"/>
  <child link="left_link1"/>
  <axis xyz="0 0 1"/>
  <limit effort="10" lower="-1.57079632675" upper="1.57079632675" velocity="10"/>
 </joint>
 <joint name="left_elbow_joint" type="revolute">
  <origin rpy="0 0 0" xyz="0.32 0 0.04685"/>
  <parent link="left_link1"/>
  <child link="left_link2"/>
  <axis xyz="0 0 1"/>
  <limit effort="10" lower="-2.615" upper="-0.349" velocity="10"/>
 </joint>
 <joint name="left_tool_joint" type="fixed">
  <origin rpy="1.57079632675 0 1.57079632675" xyz=".255 0 0"/>
  <parent link="left_link2"/>
  <child link="left_tool_link"/>
 </joint>
 <joint name="right_base_joint" type="fixed">
  <origin rpy="0 0 -0.785398163375" xyz="0.18384776309900003 -0.18384776309900003 .3475"/>
  <parent link="base_link"/>
  <child link="right_link0"/>
 </joint>
 <link name="right_link0">
  <visual>
   <origin rpy="0 0 0" xyz="0 0 0"/>
   <geometry>
    <mesh filename="package://levion_arm_ros2_control/mesh/Link0.STL" scale="1 1 1"/>
   </geometry>
   <material name="levion_black">
    <color rgba="0.3 0.3 0.3 1.0"/>
   </material>
  </visual>
  <collision>
   <origin rpy="0 0 0" xyz="0 0 0"/>
   <geometry>
    <mesh filename="package://levion_arm_ros2_control/mesh/Link0.STL" scale="1 1 1"/>
   </geometry>
  </collision>
  <inertial>
   <origin rpy="0 0 0" xyz="0 0 0"/>
   <mass value="0.5"/>
   <inertia ixx="0.0005" ixy="0.0" ixz="0.0" iyy="0.0005" iyz="0.0" izz="0.0005"/>
  </inertial>
 </link>
 <link name="right_link1">
  <visual>
   <origin rpy="0 0 0" xyz="0 0 0"/>
   <geometry>
    <mesh filename="package://levion_arm_ros2_control/mesh/Link1.STL" scale="1 1 1"/>
   </geometry>
   <material name="levion_black">
    <color rgba="0.3 0.3 0.3 1.0"/>
   </material>
  </visual>
  <collision>
   <origin rpy="0 0 0" xyz="0 0 0"/>
   <geometry>
    <mesh filename="package://levion_arm_ros2_control/mesh/Link1.STL" scale="1 1 1"/>
   </geometry>
  </collision>
  <inertial>
   <origin rpy="0 0 0" xyz="0.05 0 0"/>
   <mass value="0.6"/>
   <inertia ixx="0.0006" ixy="0.0" ixz="0.0" iyy="0.0006" iyz="0.0" izz="0.0006"/>
  </inertial>
 </link>
 <link name="right_link2">
  <visual>
   <origin rpy="0 0 0" xyz="0 0 0"/>
   <geometry>
    <mesh filename="package://levion_arm_ros2_control/mesh/Link2.STL" scale="1 1 1"/>
   </geometry>
   <material name="levion_black">
    <color rgba="0.3 0.3 0.3 1.0"/>
   </material>
  </visual>
  <collision>
   <origin rpy="0 0 0" xyz="0 0 0"/>
   <geometry>
    <mesh filename="package://levion_arm_ros2_control/mesh/Link2.STL" scale="1 1 1"/>
   </geometry>
  </collision>
  <inertial>
   <origin rpy="0 0 0" xyz="0 0 0"/>
   <mass value="0.1"/>
   <inertia ixx="0.0001" ixy="0.0" ixz="0.0" iyy="0.0001" iyz="0.0" izz="0.0001"/>
  </inertial>
 </link>
 <link name="right_tool_link">
  </link>
 <joint name="right_shoulder_joint" type="revolute">
  <origin rpy="0 0 0" xyz="0 0 0.0439"/>
  <parent link="right_link0"/>
  <child link="right_link1"/>
  <axis xyz="0 0 1"/>
  <limit effort="10" lower="-1.57079632675" upper="1.57079632675" velocity="10"/>
 </joint>
 <joint name="right_elbow_joint" type="revolute">
  <origin rpy="0 0 0" xyz="0.32 0 0.04685"/>
  <parent link="right_link1"/>
  <child link="right_link2"/>
  <axis xyz="0 0 1"/>
  <limit effort="10" lower="0.349" upper="2.615" velocity="10"/>
 </joint>
 <joint name="right_tool_joint" type="fixed">
  <origin rpy="1.57079632675 0 1.57079632675" xyz=".255 0 0"/>
  <parent link="right_link2"/>
  <child link="right_tool_link"/>
 </joint>
 <!-- real/mujoco -->
 <ros2_control name="RwSystem" type="system">
  <hardware>
   <plugin>mujoco_ros2_control/MujocoSystem</plugin>
  </hardware>
  <joint name="rw_joint">
   <command_interface name="position">
    <param name="min">-1</param>
    <param name="max">1</param>
   </command_interface>
   <state_interface name="position"/>
   <state_interface name="velocity"/>
   <state_interface name="effort"/>
   <param name="node_id">0</param>
  </joint>
 </ros2_control>
 <!-- real/mujoco-->
 <ros2_control name="levion_arm" type="system">
  <hardware>
   <plugin>mujoco_ros2_control/MujocoSystem</plugin>
  </hardware>
  <joint name="left_shoulder_joint">
   <!-- ros2 control basic setting -->
   <command_interface name="position">
    <param name="min">-1.57079632675</param>
    <param name="max">1.57079632675</param>
   </command_interface>
   <command_interface name="velocity">
    <param name="min">-10</param>
    <param name="max">10</param>
   </command_interface>
   <command_interface name="effort">
    <param name="min">-10</param>
    <param name="max">10</param>
   </command_interface>
   <state_interface name="position"/>
   <state_interface name="velocity"/>
   <state_interface name="effort"/>
   <state_interface name="temperature"/>
   <!-- cubemars hardware settings -->
   <param name="can_id">104</param>
   <param name="pole_pairs">21</param>
   <param name="gear_ratio">8</param>
   <param name="kt">0.199</param>
   <!-- levion arm settings -->
   <param name="pos_limit_min">-1.57079632675</param>
   <param name="pos_limit_max">1.57079632675</param>
   <param name="enc_off">0</param>
  </joint>
  <joint name="left_elbow_joint">
   <!-- ros2 control basic setting -->
   <command_interface name="position">
    <param name="min">-2.615</param>
    <param name="max">-0.349</param>
   </command_interface>
   <command_interface name="velocity">
    <param name="min">-10</param>
    <param name="max">10</param>
   </command_interface>
   <command_interface name="effort">
    <param name="min">-10</param>
    <param name="max">10</param>
   </command_interface>
   <state_interface name="position"/>
   <state_interface name="velocity"/>
   <state_interface name="effort"/>
   <state_interface name="temperature"/>
   <!-- cubemars hardware settings -->
   <param name="can_id">105</param>
   <param name="pole_pairs">21</param>
   <param name="gear_ratio">8</param>
   <param name="kt">0.199</param>
   <!-- levion arm settings -->
   <param name="pos_limit_min">-2.615</param>
   <param name="pos_limit_max">-0.349</param>
   <param name="enc_off">0.349</param>
  </joint>
  <joint name="right_shoulder_joint">
   <!-- ros2 control basic setting -->
   <command_interface name="position">
    <param name="min">-1.57079632675</param>
    <param name="max">1.57079632675</param>
   </command_interface>
   <command_interface name="velocity">
    <param name="min">-10</param>
    <param name="max">10</param>
   </command_interface>
   <command_interface name="effort">
    <param name="min">-10</param>
    <param name="max">10</param>
   </command_interface>
   <state_interface name="position"/>
   <state_interface name="velocity"/>
   <state_interface name="effort"/>
   <state_interface name="temperature"/>
   <!-- cubemars hardware settings -->
   <param name="can_id">204</param>
   <param name="pole_pairs">21</param>
   <param name="gear_ratio">8</param>
   <param name="kt">0.199</param>
   <!-- levion arm settings -->
   <param name="pos_limit_min">-1.57079632675</param>
   <param name="pos_limit_max">1.57079632675</param>
   <param name="enc_off">0</param>
  </joint>
  <joint name="right_elbow_joint">
   <!-- ros2 control basic setting -->
   <command_interface name="position">
    <param name="min">0.349</param>
    <param name="max">2.615</param>
   </command_interface>
   <command_interface name="velocity">
    <param name="min">-10</param>
    <param name="max">10</param>
   </command_interface>
   <command_interface name="effort">
    <param name="min">-10</param>
    <param name="max">10</param>
   </command_interface>
   <state_interface name="position"/>
   <state_interface name="velocity"/>
   <state_interface name="effort"/>
   <state_interface name="temperature"/>
   <!-- cubemars hardware settings -->
   <param name="can_id">205</param>
   <param name="pole_pairs">21</param>
   <param name="gear_ratio">8</param>
   <param name="kt">0.199</param>
   <!-- levion arm settings -->
   <param name="pos_limit_min">0.349</param>
   <param name="pos_limit_max">2.615</param>
   <param name="enc_off">-0.349</param>
  </joint>
 </ros2_control>
</robot>
